{
 "cells": [
  {
   "cell_type": "code",
   "execution_count": 12,
   "id": "84aac204",
   "metadata": {},
   "outputs": [
    {
     "name": "stdout",
     "output_type": "stream",
     "text": [
      "2.1.0\n",
      "ERROR! Session/line number was not unique in database. History logging moved to new session 61\n"
     ]
    }
   ],
   "source": [
    "import tensorflow as tf\n",
    "from tensorflow import keras\n",
    "\n",
    "import numpy as np\n",
    "\n",
    "print(tf.__version__)"
   ]
  },
  {
   "cell_type": "code",
   "execution_count": 3,
   "id": "48152d78",
   "metadata": {},
   "outputs": [
    {
     "name": "stderr",
     "output_type": "stream",
     "text": [
      "C:\\Users\\zlope\\miniconda3\\envs\\tensorflow\\lib\\site-packages\\tensorflow_core\\python\\keras\\datasets\\imdb.py:129: VisibleDeprecationWarning: Creating an ndarray from ragged nested sequences (which is a list-or-tuple of lists-or-tuples-or ndarrays with different lengths or shapes) is deprecated. If you meant to do this, you must specify 'dtype=object' when creating the ndarray\n",
      "  x_train, y_train = np.array(xs[:idx]), np.array(labels[:idx])\n",
      "C:\\Users\\zlope\\miniconda3\\envs\\tensorflow\\lib\\site-packages\\tensorflow_core\\python\\keras\\datasets\\imdb.py:130: VisibleDeprecationWarning: Creating an ndarray from ragged nested sequences (which is a list-or-tuple of lists-or-tuples-or ndarrays with different lengths or shapes) is deprecated. If you meant to do this, you must specify 'dtype=object' when creating the ndarray\n",
      "  x_test, y_test = np.array(xs[idx:]), np.array(labels[idx:])\n"
     ]
    }
   ],
   "source": [
    "imdb = keras.datasets.imdb\n",
    "\n",
    "(train_data, train_labels), (test_data, test_labels) = imdb.load_data(num_words=10000)"
   ]
  },
  {
   "cell_type": "code",
   "execution_count": 4,
   "id": "c291241a",
   "metadata": {},
   "outputs": [
    {
     "name": "stdout",
     "output_type": "stream",
     "text": [
      "Training entries: 25000, labels: 25000\n"
     ]
    }
   ],
   "source": [
    "print(\"Training entries: {}, labels: {}\".format(len(train_data), len(train_labels)))"
   ]
  },
  {
   "cell_type": "code",
   "execution_count": 5,
   "id": "940e408c",
   "metadata": {},
   "outputs": [
    {
     "name": "stdout",
     "output_type": "stream",
     "text": [
      "Training entries: 25000, labels: 25000\n"
     ]
    }
   ],
   "source": [
    "print('Training entries: {}, labels: {}'.format(len(test_data), len(test_labels)))"
   ]
  },
  {
   "cell_type": "code",
   "execution_count": 6,
   "id": "7b23d57c",
   "metadata": {},
   "outputs": [
    {
     "name": "stdout",
     "output_type": "stream",
     "text": [
      "[1, 14, 22, 16, 43, 530, 973, 1622, 1385, 65, 458, 4468, 66, 3941, 4, 173, 36, 256, 5, 25, 100, 43, 838, 112, 50, 670, 2, 9, 35, 480, 284, 5, 150, 4, 172, 112, 167, 2, 336, 385, 39, 4, 172, 4536, 1111, 17, 546, 38, 13, 447, 4, 192, 50, 16, 6, 147, 2025, 19, 14, 22, 4, 1920, 4613, 469, 4, 22, 71, 87, 12, 16, 43, 530, 38, 76, 15, 13, 1247, 4, 22, 17, 515, 17, 12, 16, 626, 18, 2, 5, 62, 386, 12, 8, 316, 8, 106, 5, 4, 2223, 5244, 16, 480, 66, 3785, 33, 4, 130, 12, 16, 38, 619, 5, 25, 124, 51, 36, 135, 48, 25, 1415, 33, 6, 22, 12, 215, 28, 77, 52, 5, 14, 407, 16, 82, 2, 8, 4, 107, 117, 5952, 15, 256, 4, 2, 7, 3766, 5, 723, 36, 71, 43, 530, 476, 26, 400, 317, 46, 7, 4, 2, 1029, 13, 104, 88, 4, 381, 15, 297, 98, 32, 2071, 56, 26, 141, 6, 194, 7486, 18, 4, 226, 22, 21, 134, 476, 26, 480, 5, 144, 30, 5535, 18, 51, 36, 28, 224, 92, 25, 104, 4, 226, 65, 16, 38, 1334, 88, 12, 16, 283, 5, 16, 4472, 113, 103, 32, 15, 16, 5345, 19, 178, 32]\n"
     ]
    }
   ],
   "source": [
    "print(train_data[0])"
   ]
  },
  {
   "cell_type": "code",
   "execution_count": 7,
   "id": "dc21d4ab",
   "metadata": {},
   "outputs": [
    {
     "data": {
      "text/plain": [
       "(218, 189)"
      ]
     },
     "execution_count": 7,
     "metadata": {},
     "output_type": "execute_result"
    }
   ],
   "source": [
    "len(train_data[0]), len(train_data[1])"
   ]
  },
  {
   "cell_type": "code",
   "execution_count": 7,
   "id": "08299ff7",
   "metadata": {},
   "outputs": [],
   "source": [
    "# Um dicionário mapeando palavras em índices inteiros\n",
    "word_index = imdb.get_word_index()\n",
    "\n",
    "# Os primeiros índices são reservados\n",
    "word_index = {k:(v+3) for k,v in word_index.items()}\n",
    "word_index[\"<PAD>\"] = 0\n",
    "word_index[\"<START>\"] = 1\n",
    "word_index[\"<UNK>\"] = 2  # unknown\n",
    "word_index[\"<UNUSED>\"] = 3\n",
    "\n",
    "reverse_word_index = dict([(value, key) for (key, value) in word_index.items()])\n",
    "\n",
    "def decode_review(text):\n",
    "    return ' '.join([reverse_word_index.get(i, '?') for i in text])"
   ]
  },
  {
   "cell_type": "code",
   "execution_count": 8,
   "id": "2c8a5d5c",
   "metadata": {},
   "outputs": [
    {
     "data": {
      "text/plain": [
       "\"<START> this film was just brilliant casting location scenery story direction everyone's really suited the part they played and you could just imagine being there robert <UNK> is an amazing actor and now the same being director <UNK> father came from the same scottish island as myself so i loved the fact there was a real connection with this film the witty remarks throughout the film were great it was just brilliant so much that i bought the film as soon as it was released for <UNK> and would recommend it to everyone to watch and the fly fishing was amazing really cried at the end it was so sad and you know what they say if you cry at a film it must have been good and this definitely was also <UNK> to the two little boy's that played the <UNK> of norman and paul they were just brilliant children are often left out of the <UNK> list i think because the stars that play them all grown up are such a big profile for the whole film but these children are amazing and should be praised for what they have done don't you think the whole story was so lovely because it was true and was someone's life after all that was shared with us all\""
      ]
     },
     "execution_count": 8,
     "metadata": {},
     "output_type": "execute_result"
    }
   ],
   "source": [
    "decode_review(train_data[0])"
   ]
  },
  {
   "cell_type": "code",
   "execution_count": 9,
   "id": "442c21cf",
   "metadata": {},
   "outputs": [],
   "source": [
    "train_data = keras.preprocessing.sequence.pad_sequences(train_data,\n",
    "                                                        value=word_index[\"<PAD>\"],\n",
    "                                                        padding='post',\n",
    "                                                        maxlen=256)\n",
    "\n",
    "test_data = keras.preprocessing.sequence.pad_sequences(test_data,\n",
    "                                                       value=word_index[\"<PAD>\"],\n",
    "                                                       padding='post',\n",
    "                                                       maxlen=256)"
   ]
  },
  {
   "cell_type": "code",
   "execution_count": 10,
   "id": "bb5d2bdd",
   "metadata": {},
   "outputs": [
    {
     "data": {
      "text/plain": [
       "(256, 256)"
      ]
     },
     "execution_count": 10,
     "metadata": {},
     "output_type": "execute_result"
    }
   ],
   "source": [
    "len(train_data[0]), len(train_data[1])"
   ]
  },
  {
   "cell_type": "code",
   "execution_count": 11,
   "id": "bdec0c9a",
   "metadata": {},
   "outputs": [
    {
     "name": "stdout",
     "output_type": "stream",
     "text": [
      "[   1   14   22   16   43  530  973 1622 1385   65  458 4468   66 3941\n",
      "    4  173   36  256    5   25  100   43  838  112   50  670    2    9\n",
      "   35  480  284    5  150    4  172  112  167    2  336  385   39    4\n",
      "  172 4536 1111   17  546   38   13  447    4  192   50   16    6  147\n",
      " 2025   19   14   22    4 1920 4613  469    4   22   71   87   12   16\n",
      "   43  530   38   76   15   13 1247    4   22   17  515   17   12   16\n",
      "  626   18    2    5   62  386   12    8  316    8  106    5    4 2223\n",
      " 5244   16  480   66 3785   33    4  130   12   16   38  619    5   25\n",
      "  124   51   36  135   48   25 1415   33    6   22   12  215   28   77\n",
      "   52    5   14  407   16   82    2    8    4  107  117 5952   15  256\n",
      "    4    2    7 3766    5  723   36   71   43  530  476   26  400  317\n",
      "   46    7    4    2 1029   13  104   88    4  381   15  297   98   32\n",
      " 2071   56   26  141    6  194 7486   18    4  226   22   21  134  476\n",
      "   26  480    5  144   30 5535   18   51   36   28  224   92   25  104\n",
      "    4  226   65   16   38 1334   88   12   16  283    5   16 4472  113\n",
      "  103   32   15   16 5345   19  178   32    0    0    0    0    0    0\n",
      "    0    0    0    0    0    0    0    0    0    0    0    0    0    0\n",
      "    0    0    0    0    0    0    0    0    0    0    0    0    0    0\n",
      "    0    0    0    0]\n"
     ]
    }
   ],
   "source": [
    "print(train_data[0])"
   ]
  },
  {
   "cell_type": "code",
   "execution_count": 17,
   "id": "35098c71",
   "metadata": {},
   "outputs": [
    {
     "name": "stdout",
     "output_type": "stream",
     "text": [
      "ERROR! Session/line number was not unique in database. History logging moved to new session 57\n",
      "Model: \"sequential_1\"\n",
      "_________________________________________________________________\n",
      "Layer (type)                 Output Shape              Param #   \n",
      "=================================================================\n",
      "embedding_1 (Embedding)      (None, None, 16)          160000    \n",
      "_________________________________________________________________\n",
      "global_average_pooling1d_1 ( (None, 16)                0         \n",
      "_________________________________________________________________\n",
      "dense_2 (Dense)              (None, 16)                272       \n",
      "_________________________________________________________________\n",
      "dense_3 (Dense)              (None, 1)                 17        \n",
      "=================================================================\n",
      "Total params: 160,289\n",
      "Trainable params: 160,289\n",
      "Non-trainable params: 0\n",
      "_________________________________________________________________\n"
     ]
    }
   ],
   "source": [
    "# O formato de entrada é a contagem vocabulário usados pelas avaliações dos filmes (10000 palavras)\n",
    "vocab_size = 10000\n",
    "\n",
    "model = keras.Sequential()\n",
    "model.add(keras.layers.Embedding(vocab_size, 16))\n",
    "model.add(keras.layers.GlobalAveragePooling1D())\n",
    "model.add(keras.layers.Dense(16, activation='relu'))\n",
    "model.add(keras.layers.Dense(1, activation='sigmoid'))\n",
    "\n",
    "model.summary()              "
   ]
  },
  {
   "cell_type": "code",
   "execution_count": null,
   "id": "3daa78a4",
   "metadata": {},
   "outputs": [
    {
     "name": "stderr",
     "output_type": "stream",
     "text": [
      "ERROR:root:Internal Python error in the inspect module.\n",
      "Below is the traceback from this internal error.\n",
      "\n",
      "ERROR:root:Internal Python error in the inspect module.\n",
      "Below is the traceback from this internal error.\n",
      "\n",
      "ERROR:root:Internal Python error in the inspect module.\n",
      "Below is the traceback from this internal error.\n",
      "\n"
     ]
    },
    {
     "name": "stdout",
     "output_type": "stream",
     "text": [
      "Traceback (most recent call last):\n",
      "  File \"C:\\Users\\zlope\\miniconda3\\envs\\tensorflow\\lib\\site-packages\\IPython\\core\\interactiveshell.py\", line 3444, in run_code\n",
      "    exec(code_obj, self.user_global_ns, self.user_ns)\n",
      "  File \"C:\\Users\\zlope\\AppData\\Local\\Temp/ipykernel_26496/791363231.py\", line 1, in <module>\n",
      "    model.compile(optimizer='adam',\n",
      "NameError: name 'model' is not defined\n",
      "\n",
      "During handling of the above exception, another exception occurred:\n",
      "\n",
      "Traceback (most recent call last):\n",
      "  File \"C:\\Users\\zlope\\miniconda3\\envs\\tensorflow\\lib\\site-packages\\IPython\\core\\interactiveshell.py\", line 2064, in showtraceback\n",
      "    stb = value._render_traceback_()\n",
      "AttributeError: 'NameError' object has no attribute '_render_traceback_'\n",
      "\n",
      "During handling of the above exception, another exception occurred:\n",
      "\n",
      "Traceback (most recent call last):\n",
      "  File \"C:\\Users\\zlope\\miniconda3\\envs\\tensorflow\\lib\\site-packages\\IPython\\core\\ultratb.py\", line 1101, in get_records\n",
      "    return _fixed_getinnerframes(etb, number_of_lines_of_context, tb_offset)\n",
      "  File \"C:\\Users\\zlope\\miniconda3\\envs\\tensorflow\\lib\\site-packages\\IPython\\core\\ultratb.py\", line 248, in wrapped\n",
      "    return f(*args, **kwargs)\n",
      "  File \"C:\\Users\\zlope\\miniconda3\\envs\\tensorflow\\lib\\site-packages\\IPython\\core\\ultratb.py\", line 281, in _fixed_getinnerframes\n",
      "    records = fix_frame_records_filenames(inspect.getinnerframes(etb, context))\n",
      "  File \"C:\\Users\\zlope\\miniconda3\\envs\\tensorflow\\lib\\inspect.py\", line 1502, in getinnerframes\n",
      "    frameinfo = (tb.tb_frame,) + getframeinfo(tb, context)\n",
      "  File \"C:\\Users\\zlope\\miniconda3\\envs\\tensorflow\\lib\\inspect.py\", line 1460, in getframeinfo\n",
      "    filename = getsourcefile(frame) or getfile(frame)\n",
      "  File \"C:\\Users\\zlope\\miniconda3\\envs\\tensorflow\\lib\\inspect.py\", line 696, in getsourcefile\n",
      "    if getattr(getmodule(object, filename), '__loader__', None) is not None:\n",
      "  File \"C:\\Users\\zlope\\miniconda3\\envs\\tensorflow\\lib\\inspect.py\", line 733, in getmodule\n",
      "    if ismodule(module) and hasattr(module, '__file__'):\n",
      "  File \"C:\\Users\\zlope\\miniconda3\\envs\\tensorflow\\lib\\site-packages\\tensorflow\\__init__.py\", line 50, in __getattr__\n",
      "    module = self._load()\n",
      "  File \"C:\\Users\\zlope\\miniconda3\\envs\\tensorflow\\lib\\site-packages\\tensorflow\\__init__.py\", line 44, in _load\n",
      "    module = _importlib.import_module(self.__name__)\n",
      "  File \"C:\\Users\\zlope\\miniconda3\\envs\\tensorflow\\lib\\importlib\\__init__.py\", line 127, in import_module\n",
      "    return _bootstrap._gcd_import(name[level:], package, level)\n",
      "  File \"<frozen importlib._bootstrap>\", line 1006, in _gcd_import\n",
      "  File \"<frozen importlib._bootstrap>\", line 983, in _find_and_load\n",
      "  File \"<frozen importlib._bootstrap>\", line 965, in _find_and_load_unlocked\n",
      "ModuleNotFoundError: No module named 'tensorflow_core.estimator'\n",
      "Traceback (most recent call last):\n",
      "  File \"C:\\Users\\zlope\\miniconda3\\envs\\tensorflow\\lib\\site-packages\\IPython\\core\\interactiveshell.py\", line 3444, in run_code\n",
      "    exec(code_obj, self.user_global_ns, self.user_ns)\n",
      "  File \"C:\\Users\\zlope\\AppData\\Local\\Temp/ipykernel_26496/791363231.py\", line 1, in <module>\n",
      "    model.compile(optimizer='adam',\n",
      "NameError: name 'model' is not defined\n",
      "\n",
      "During handling of the above exception, another exception occurred:\n",
      "\n",
      "Traceback (most recent call last):\n",
      "  File \"C:\\Users\\zlope\\miniconda3\\envs\\tensorflow\\lib\\site-packages\\IPython\\core\\interactiveshell.py\", line 2064, in showtraceback\n",
      "    stb = value._render_traceback_()\n",
      "AttributeError: 'NameError' object has no attribute '_render_traceback_'\n",
      "\n",
      "During handling of the above exception, another exception occurred:\n",
      "\n",
      "Traceback (most recent call last):\n",
      "  File \"C:\\Users\\zlope\\miniconda3\\envs\\tensorflow\\lib\\site-packages\\IPython\\core\\interactiveshell.py\", line 3364, in run_ast_nodes\n",
      "    if (await self.run_code(code, result,  async_=asy)):\n",
      "  File \"C:\\Users\\zlope\\miniconda3\\envs\\tensorflow\\lib\\site-packages\\IPython\\core\\interactiveshell.py\", line 3461, in run_code\n",
      "    self.showtraceback(running_compiled_code=True)\n",
      "  File \"C:\\Users\\zlope\\miniconda3\\envs\\tensorflow\\lib\\site-packages\\IPython\\core\\interactiveshell.py\", line 2067, in showtraceback\n",
      "    value, tb, tb_offset=tb_offset)\n",
      "  File \"C:\\Users\\zlope\\miniconda3\\envs\\tensorflow\\lib\\site-packages\\IPython\\core\\ultratb.py\", line 1368, in structured_traceback\n",
      "    self, etype, value, tb, tb_offset, number_of_lines_of_context)\n",
      "  File \"C:\\Users\\zlope\\miniconda3\\envs\\tensorflow\\lib\\site-packages\\IPython\\core\\ultratb.py\", line 1268, in structured_traceback\n",
      "    self, etype, value, tb, tb_offset, number_of_lines_of_context\n",
      "  File \"C:\\Users\\zlope\\miniconda3\\envs\\tensorflow\\lib\\site-packages\\IPython\\core\\ultratb.py\", line 1125, in structured_traceback\n",
      "    tb_offset)\n",
      "  File \"C:\\Users\\zlope\\miniconda3\\envs\\tensorflow\\lib\\site-packages\\IPython\\core\\ultratb.py\", line 1082, in format_exception_as_a_whole\n",
      "    last_unique, recursion_repeat = find_recursion(orig_etype, evalue, records)\n",
      "  File \"C:\\Users\\zlope\\miniconda3\\envs\\tensorflow\\lib\\site-packages\\IPython\\core\\ultratb.py\", line 382, in find_recursion\n",
      "    return len(records), 0\n",
      "TypeError: object of type 'NoneType' has no len()\n",
      "\n",
      "During handling of the above exception, another exception occurred:\n",
      "\n",
      "Traceback (most recent call last):\n",
      "  File \"C:\\Users\\zlope\\miniconda3\\envs\\tensorflow\\lib\\site-packages\\IPython\\core\\interactiveshell.py\", line 2064, in showtraceback\n",
      "    stb = value._render_traceback_()\n",
      "AttributeError: 'TypeError' object has no attribute '_render_traceback_'\n",
      "\n",
      "During handling of the above exception, another exception occurred:\n",
      "\n",
      "Traceback (most recent call last):\n",
      "  File \"C:\\Users\\zlope\\miniconda3\\envs\\tensorflow\\lib\\site-packages\\IPython\\core\\ultratb.py\", line 1101, in get_records\n",
      "    return _fixed_getinnerframes(etb, number_of_lines_of_context, tb_offset)\n",
      "  File \"C:\\Users\\zlope\\miniconda3\\envs\\tensorflow\\lib\\site-packages\\IPython\\core\\ultratb.py\", line 248, in wrapped\n",
      "    return f(*args, **kwargs)\n",
      "  File \"C:\\Users\\zlope\\miniconda3\\envs\\tensorflow\\lib\\site-packages\\IPython\\core\\ultratb.py\", line 281, in _fixed_getinnerframes\n",
      "    records = fix_frame_records_filenames(inspect.getinnerframes(etb, context))\n",
      "  File \"C:\\Users\\zlope\\miniconda3\\envs\\tensorflow\\lib\\inspect.py\", line 1502, in getinnerframes\n",
      "    frameinfo = (tb.tb_frame,) + getframeinfo(tb, context)\n",
      "  File \"C:\\Users\\zlope\\miniconda3\\envs\\tensorflow\\lib\\inspect.py\", line 1460, in getframeinfo\n",
      "    filename = getsourcefile(frame) or getfile(frame)\n",
      "  File \"C:\\Users\\zlope\\miniconda3\\envs\\tensorflow\\lib\\inspect.py\", line 696, in getsourcefile\n",
      "    if getattr(getmodule(object, filename), '__loader__', None) is not None:\n",
      "  File \"C:\\Users\\zlope\\miniconda3\\envs\\tensorflow\\lib\\inspect.py\", line 733, in getmodule\n",
      "    if ismodule(module) and hasattr(module, '__file__'):\n",
      "  File \"C:\\Users\\zlope\\miniconda3\\envs\\tensorflow\\lib\\site-packages\\tensorflow\\__init__.py\", line 50, in __getattr__\n",
      "    module = self._load()\n",
      "  File \"C:\\Users\\zlope\\miniconda3\\envs\\tensorflow\\lib\\site-packages\\tensorflow\\__init__.py\", line 44, in _load\n",
      "    module = _importlib.import_module(self.__name__)\n",
      "  File \"C:\\Users\\zlope\\miniconda3\\envs\\tensorflow\\lib\\importlib\\__init__.py\", line 127, in import_module\n",
      "    return _bootstrap._gcd_import(name[level:], package, level)\n",
      "  File \"<frozen importlib._bootstrap>\", line 1006, in _gcd_import\n",
      "  File \"<frozen importlib._bootstrap>\", line 983, in _find_and_load\n",
      "  File \"<frozen importlib._bootstrap>\", line 965, in _find_and_load_unlocked\n",
      "ModuleNotFoundError: No module named 'tensorflow_core.estimator'\n",
      "ERROR! Session/line number was not unique in database. History logging moved to new session 60\n",
      "Traceback (most recent call last):\n",
      "  File \"C:\\Users\\zlope\\miniconda3\\envs\\tensorflow\\lib\\site-packages\\IPython\\core\\interactiveshell.py\", line 3444, in run_code\n",
      "    exec(code_obj, self.user_global_ns, self.user_ns)\n",
      "  File \"C:\\Users\\zlope\\AppData\\Local\\Temp/ipykernel_26496/791363231.py\", line 1, in <module>\n",
      "    model.compile(optimizer='adam',\n",
      "NameError: name 'model' is not defined\n",
      "\n",
      "During handling of the above exception, another exception occurred:\n",
      "\n",
      "Traceback (most recent call last):\n",
      "  File \"C:\\Users\\zlope\\miniconda3\\envs\\tensorflow\\lib\\site-packages\\IPython\\core\\interactiveshell.py\", line 2064, in showtraceback\n",
      "    stb = value._render_traceback_()\n",
      "AttributeError: 'NameError' object has no attribute '_render_traceback_'\n",
      "\n",
      "During handling of the above exception, another exception occurred:\n",
      "\n",
      "Traceback (most recent call last):\n",
      "  File \"C:\\Users\\zlope\\miniconda3\\envs\\tensorflow\\lib\\site-packages\\IPython\\core\\interactiveshell.py\", line 3364, in run_ast_nodes\n",
      "    if (await self.run_code(code, result,  async_=asy)):\n",
      "  File \"C:\\Users\\zlope\\miniconda3\\envs\\tensorflow\\lib\\site-packages\\IPython\\core\\interactiveshell.py\", line 3461, in run_code\n",
      "    self.showtraceback(running_compiled_code=True)\n",
      "  File \"C:\\Users\\zlope\\miniconda3\\envs\\tensorflow\\lib\\site-packages\\IPython\\core\\interactiveshell.py\", line 2067, in showtraceback\n",
      "    value, tb, tb_offset=tb_offset)\n",
      "  File \"C:\\Users\\zlope\\miniconda3\\envs\\tensorflow\\lib\\site-packages\\IPython\\core\\ultratb.py\", line 1368, in structured_traceback\n",
      "    self, etype, value, tb, tb_offset, number_of_lines_of_context)\n",
      "  File \"C:\\Users\\zlope\\miniconda3\\envs\\tensorflow\\lib\\site-packages\\IPython\\core\\ultratb.py\", line 1268, in structured_traceback\n",
      "    self, etype, value, tb, tb_offset, number_of_lines_of_context\n",
      "  File \"C:\\Users\\zlope\\miniconda3\\envs\\tensorflow\\lib\\site-packages\\IPython\\core\\ultratb.py\", line 1125, in structured_traceback\n",
      "    tb_offset)\n",
      "  File \"C:\\Users\\zlope\\miniconda3\\envs\\tensorflow\\lib\\site-packages\\IPython\\core\\ultratb.py\", line 1082, in format_exception_as_a_whole\n",
      "    last_unique, recursion_repeat = find_recursion(orig_etype, evalue, records)\n",
      "  File \"C:\\Users\\zlope\\miniconda3\\envs\\tensorflow\\lib\\site-packages\\IPython\\core\\ultratb.py\", line 382, in find_recursion\n",
      "    return len(records), 0\n",
      "TypeError: object of type 'NoneType' has no len()\n",
      "\n",
      "During handling of the above exception, another exception occurred:\n",
      "\n",
      "Traceback (most recent call last):\n",
      "  File \"C:\\Users\\zlope\\miniconda3\\envs\\tensorflow\\lib\\site-packages\\IPython\\core\\interactiveshell.py\", line 2064, in showtraceback\n",
      "    stb = value._render_traceback_()\n",
      "AttributeError: 'TypeError' object has no attribute '_render_traceback_'\n",
      "\n",
      "During handling of the above exception, another exception occurred:\n",
      "\n",
      "Traceback (most recent call last):\n",
      "  File \"C:\\Users\\zlope\\miniconda3\\envs\\tensorflow\\lib\\site-packages\\IPython\\core\\interactiveshell.py\", line 2947, in _run_cell\n",
      "    return runner(coro)\n",
      "  File \"C:\\Users\\zlope\\miniconda3\\envs\\tensorflow\\lib\\site-packages\\IPython\\core\\async_helpers.py\", line 68, in _pseudo_sync_runner\n",
      "    coro.send(None)\n",
      "  File \"C:\\Users\\zlope\\miniconda3\\envs\\tensorflow\\lib\\site-packages\\IPython\\core\\interactiveshell.py\", line 3173, in run_cell_async\n",
      "    interactivity=interactivity, compiler=compiler, result=result)\n",
      "  File \"C:\\Users\\zlope\\miniconda3\\envs\\tensorflow\\lib\\site-packages\\IPython\\core\\interactiveshell.py\", line 3383, in run_ast_nodes\n",
      "    self.showtraceback()\n",
      "  File \"C:\\Users\\zlope\\miniconda3\\envs\\tensorflow\\lib\\site-packages\\IPython\\core\\interactiveshell.py\", line 2067, in showtraceback\n",
      "    value, tb, tb_offset=tb_offset)\n",
      "  File \"C:\\Users\\zlope\\miniconda3\\envs\\tensorflow\\lib\\site-packages\\IPython\\core\\ultratb.py\", line 1368, in structured_traceback\n",
      "    self, etype, value, tb, tb_offset, number_of_lines_of_context)\n",
      "  File \"C:\\Users\\zlope\\miniconda3\\envs\\tensorflow\\lib\\site-packages\\IPython\\core\\ultratb.py\", line 1268, in structured_traceback\n",
      "    self, etype, value, tb, tb_offset, number_of_lines_of_context\n",
      "  File \"C:\\Users\\zlope\\miniconda3\\envs\\tensorflow\\lib\\site-packages\\IPython\\core\\ultratb.py\", line 1143, in structured_traceback\n",
      "    chained_exceptions_tb_offset)\n",
      "  File \"C:\\Users\\zlope\\miniconda3\\envs\\tensorflow\\lib\\site-packages\\IPython\\core\\ultratb.py\", line 1082, in format_exception_as_a_whole\n",
      "    last_unique, recursion_repeat = find_recursion(orig_etype, evalue, records)\n",
      "  File \"C:\\Users\\zlope\\miniconda3\\envs\\tensorflow\\lib\\site-packages\\IPython\\core\\ultratb.py\", line 382, in find_recursion\n",
      "    return len(records), 0\n",
      "TypeError: object of type 'NoneType' has no len()\n",
      "\n",
      "During handling of the above exception, another exception occurred:\n",
      "\n",
      "Traceback (most recent call last):\n",
      "  File \"C:\\Users\\zlope\\miniconda3\\envs\\tensorflow\\lib\\site-packages\\IPython\\core\\interactiveshell.py\", line 2064, in showtraceback\n",
      "    stb = value._render_traceback_()\n",
      "AttributeError: 'TypeError' object has no attribute '_render_traceback_'\n",
      "\n",
      "During handling of the above exception, another exception occurred:\n",
      "\n",
      "Traceback (most recent call last):\n",
      "  File \"C:\\Users\\zlope\\miniconda3\\envs\\tensorflow\\lib\\site-packages\\IPython\\core\\ultratb.py\", line 1101, in get_records\n",
      "    return _fixed_getinnerframes(etb, number_of_lines_of_context, tb_offset)\n",
      "  File \"C:\\Users\\zlope\\miniconda3\\envs\\tensorflow\\lib\\site-packages\\IPython\\core\\ultratb.py\", line 248, in wrapped\n",
      "    return f(*args, **kwargs)\n",
      "  File \"C:\\Users\\zlope\\miniconda3\\envs\\tensorflow\\lib\\site-packages\\IPython\\core\\ultratb.py\", line 281, in _fixed_getinnerframes\n",
      "    records = fix_frame_records_filenames(inspect.getinnerframes(etb, context))\n",
      "  File \"C:\\Users\\zlope\\miniconda3\\envs\\tensorflow\\lib\\inspect.py\", line 1502, in getinnerframes\n",
      "    frameinfo = (tb.tb_frame,) + getframeinfo(tb, context)\n",
      "  File \"C:\\Users\\zlope\\miniconda3\\envs\\tensorflow\\lib\\inspect.py\", line 1460, in getframeinfo\n",
      "    filename = getsourcefile(frame) or getfile(frame)\n",
      "  File \"C:\\Users\\zlope\\miniconda3\\envs\\tensorflow\\lib\\inspect.py\", line 696, in getsourcefile\n",
      "    if getattr(getmodule(object, filename), '__loader__', None) is not None:\n",
      "  File \"C:\\Users\\zlope\\miniconda3\\envs\\tensorflow\\lib\\inspect.py\", line 733, in getmodule\n",
      "    if ismodule(module) and hasattr(module, '__file__'):\n",
      "  File \"C:\\Users\\zlope\\miniconda3\\envs\\tensorflow\\lib\\site-packages\\tensorflow\\__init__.py\", line 50, in __getattr__\n",
      "    module = self._load()\n",
      "  File \"C:\\Users\\zlope\\miniconda3\\envs\\tensorflow\\lib\\site-packages\\tensorflow\\__init__.py\", line 44, in _load\n",
      "    module = _importlib.import_module(self.__name__)\n",
      "  File \"C:\\Users\\zlope\\miniconda3\\envs\\tensorflow\\lib\\importlib\\__init__.py\", line 127, in import_module\n",
      "    return _bootstrap._gcd_import(name[level:], package, level)\n",
      "  File \"<frozen importlib._bootstrap>\", line 1006, in _gcd_import\n",
      "  File \"<frozen importlib._bootstrap>\", line 983, in _find_and_load\n",
      "  File \"<frozen importlib._bootstrap>\", line 965, in _find_and_load_unlocked\n",
      "ModuleNotFoundError: No module named 'tensorflow_core.estimator'\n"
     ]
    }
   ],
   "source": [
    "model.compile(optimizer='adam',\n",
    "              loss='binary_crossentropy',\n",
    "              metrics=['accuracy'])"
   ]
  },
  {
   "cell_type": "code",
   "execution_count": 19,
   "id": "160054ea",
   "metadata": {},
   "outputs": [],
   "source": [
    "x_val = train_data[:10000]\n",
    "partial_x_train = train_data[10000:]\n",
    "\n",
    "y_val = train_labels[:10000]\n",
    "partial_y_train = train_labels[10000:]"
   ]
  },
  {
   "cell_type": "code",
   "execution_count": 20,
   "id": "715b8149",
   "metadata": {},
   "outputs": [
    {
     "data": {
      "text/plain": [
       "array([[   1,   13,  104, ...,    0,    0,    0],\n",
       "       [   1,   14,   20, ...,    0,    0,    0],\n",
       "       [   1,   86,  125, ...,    0,    0,    0],\n",
       "       ...,\n",
       "       [   1,   11,    6, ...,    0,    0,    0],\n",
       "       [   1, 1446, 7079, ...,    0,    0,    0],\n",
       "       [   1,   17,    6, ...,    0,    0,    0]])"
      ]
     },
     "execution_count": 20,
     "metadata": {},
     "output_type": "execute_result"
    }
   ],
   "source": [
    "partial_x_train"
   ]
  },
  {
   "cell_type": "code",
   "execution_count": null,
   "id": "05486a02",
   "metadata": {},
   "outputs": [
    {
     "name": "stdout",
     "output_type": "stream",
     "text": [
      "Train on 15000 samples, validate on 10000 samples\n",
      "Epoch 1/40\n",
      "  512/15000 [>.............................] - ETA: 11s"
     ]
    },
    {
     "name": "stderr",
     "output_type": "stream",
     "text": [
      "ERROR:root:Internal Python error in the inspect module.\n",
      "Below is the traceback from this internal error.\n",
      "\n",
      "ERROR:root:Internal Python error in the inspect module.\n",
      "Below is the traceback from this internal error.\n",
      "\n",
      "ERROR:root:Internal Python error in the inspect module.\n",
      "Below is the traceback from this internal error.\n",
      "\n"
     ]
    },
    {
     "name": "stdout",
     "output_type": "stream",
     "text": [
      "Traceback (most recent call last):\n",
      "  File \"C:\\Users\\zlope\\miniconda3\\envs\\tensorflow\\lib\\site-packages\\IPython\\core\\interactiveshell.py\", line 3444, in run_code\n",
      "    exec(code_obj, self.user_global_ns, self.user_ns)\n",
      "  File \"C:\\Users\\zlope\\AppData\\Local\\Temp/ipykernel_4588/3990386595.py\", line 6, in <module>\n",
      "    verbose=1)\n",
      "  File \"C:\\Users\\zlope\\miniconda3\\envs\\tensorflow\\lib\\site-packages\\tensorflow_core\\python\\keras\\engine\\training.py\", line 819, in fit\n",
      "    use_multiprocessing=use_multiprocessing)\n",
      "  File \"C:\\Users\\zlope\\miniconda3\\envs\\tensorflow\\lib\\site-packages\\tensorflow_core\\python\\keras\\engine\\training_v2.py\", line 342, in fit\n",
      "    total_epochs=epochs)\n",
      "  File \"C:\\Users\\zlope\\miniconda3\\envs\\tensorflow\\lib\\site-packages\\tensorflow_core\\python\\keras\\engine\\training_v2.py\", line 128, in run_one_epoch\n",
      "    batch_outs = execution_function(iterator)\n",
      "  File \"C:\\Users\\zlope\\miniconda3\\envs\\tensorflow\\lib\\site-packages\\tensorflow_core\\python\\keras\\engine\\training_v2_utils.py\", line 98, in execution_function\n",
      "    distributed_function(input_fn))\n",
      "  File \"C:\\Users\\zlope\\miniconda3\\envs\\tensorflow\\lib\\site-packages\\tensorflow_core\\python\\eager\\def_function.py\", line 568, in __call__\n",
      "    result = self._call(*args, **kwds)\n",
      "  File \"C:\\Users\\zlope\\miniconda3\\envs\\tensorflow\\lib\\site-packages\\tensorflow_core\\python\\eager\\def_function.py\", line 632, in _call\n",
      "    return self._stateless_fn(*args, **kwds)\n",
      "  File \"C:\\Users\\zlope\\miniconda3\\envs\\tensorflow\\lib\\site-packages\\tensorflow_core\\python\\eager\\function.py\", line 2363, in __call__\n",
      "    return graph_function._filtered_call(args, kwargs)  # pylint: disable=protected-access\n",
      "  File \"C:\\Users\\zlope\\miniconda3\\envs\\tensorflow\\lib\\site-packages\\tensorflow_core\\python\\eager\\function.py\", line 1611, in _filtered_call\n",
      "    self.captured_inputs)\n",
      "  File \"C:\\Users\\zlope\\miniconda3\\envs\\tensorflow\\lib\\site-packages\\tensorflow_core\\python\\eager\\function.py\", line 1692, in _call_flat\n",
      "    ctx, args, cancellation_manager=cancellation_manager))\n",
      "  File \"C:\\Users\\zlope\\miniconda3\\envs\\tensorflow\\lib\\site-packages\\tensorflow_core\\python\\eager\\function.py\", line 545, in call\n",
      "    ctx=ctx)\n",
      "  File \"C:\\Users\\zlope\\miniconda3\\envs\\tensorflow\\lib\\site-packages\\tensorflow_core\\python\\eager\\execute.py\", line 67, in quick_execute\n",
      "    six.raise_from(core._status_to_exception(e.code, message), None)\n",
      "  File \"<string>\", line 3, in raise_from\n",
      "tensorflow.python.framework.errors_impl.InternalError: 2 root error(s) found.\n",
      "  (0) Internal:  Blas GEMM launch failed : a.shape=(512, 16), b.shape=(16, 16), m=512, n=16, k=16\n",
      "\t [[node sequential_1/dense_2/MatMul (defined at \\AppData\\Local\\Temp/ipykernel_4588/3990386595.py:6) ]]\n",
      "  (1) Internal:  Blas GEMM launch failed : a.shape=(512, 16), b.shape=(16, 16), m=512, n=16, k=16\n",
      "\t [[node sequential_1/dense_2/MatMul (defined at \\AppData\\Local\\Temp/ipykernel_4588/3990386595.py:6) ]]\n",
      "\t [[Reshape_12/_46]]\n",
      "0 successful operations.\n",
      "0 derived errors ignored. [Op:__inference_distributed_function_1967]\n",
      "\n",
      "Function call stack:\n",
      "distributed_function -> distributed_function\n",
      "\n",
      "\n",
      "During handling of the above exception, another exception occurred:\n",
      "\n",
      "Traceback (most recent call last):\n",
      "  File \"C:\\Users\\zlope\\miniconda3\\envs\\tensorflow\\lib\\site-packages\\IPython\\core\\interactiveshell.py\", line 2064, in showtraceback\n",
      "    stb = value._render_traceback_()\n",
      "AttributeError: 'InternalError' object has no attribute '_render_traceback_'\n",
      "\n",
      "During handling of the above exception, another exception occurred:\n",
      "\n",
      "Traceback (most recent call last):\n",
      "  File \"C:\\Users\\zlope\\miniconda3\\envs\\tensorflow\\lib\\site-packages\\IPython\\core\\ultratb.py\", line 1101, in get_records\n",
      "    return _fixed_getinnerframes(etb, number_of_lines_of_context, tb_offset)\n",
      "  File \"C:\\Users\\zlope\\miniconda3\\envs\\tensorflow\\lib\\site-packages\\IPython\\core\\ultratb.py\", line 248, in wrapped\n",
      "    return f(*args, **kwargs)\n",
      "  File \"C:\\Users\\zlope\\miniconda3\\envs\\tensorflow\\lib\\site-packages\\IPython\\core\\ultratb.py\", line 281, in _fixed_getinnerframes\n",
      "    records = fix_frame_records_filenames(inspect.getinnerframes(etb, context))\n",
      "  File \"C:\\Users\\zlope\\miniconda3\\envs\\tensorflow\\lib\\inspect.py\", line 1502, in getinnerframes\n",
      "    frameinfo = (tb.tb_frame,) + getframeinfo(tb, context)\n",
      "  File \"C:\\Users\\zlope\\miniconda3\\envs\\tensorflow\\lib\\inspect.py\", line 1460, in getframeinfo\n",
      "    filename = getsourcefile(frame) or getfile(frame)\n",
      "  File \"C:\\Users\\zlope\\miniconda3\\envs\\tensorflow\\lib\\inspect.py\", line 696, in getsourcefile\n",
      "    if getattr(getmodule(object, filename), '__loader__', None) is not None:\n",
      "  File \"C:\\Users\\zlope\\miniconda3\\envs\\tensorflow\\lib\\inspect.py\", line 733, in getmodule\n",
      "    if ismodule(module) and hasattr(module, '__file__'):\n",
      "  File \"C:\\Users\\zlope\\miniconda3\\envs\\tensorflow\\lib\\site-packages\\tensorflow\\__init__.py\", line 50, in __getattr__\n",
      "    module = self._load()\n",
      "  File \"C:\\Users\\zlope\\miniconda3\\envs\\tensorflow\\lib\\site-packages\\tensorflow\\__init__.py\", line 44, in _load\n",
      "    module = _importlib.import_module(self.__name__)\n",
      "  File \"C:\\Users\\zlope\\miniconda3\\envs\\tensorflow\\lib\\importlib\\__init__.py\", line 127, in import_module\n",
      "    return _bootstrap._gcd_import(name[level:], package, level)\n",
      "  File \"<frozen importlib._bootstrap>\", line 1006, in _gcd_import\n",
      "  File \"<frozen importlib._bootstrap>\", line 983, in _find_and_load\n",
      "  File \"<frozen importlib._bootstrap>\", line 965, in _find_and_load_unlocked\n",
      "ModuleNotFoundError: No module named 'tensorflow_core.estimator'\n",
      "Traceback (most recent call last):\n",
      "  File \"C:\\Users\\zlope\\miniconda3\\envs\\tensorflow\\lib\\site-packages\\IPython\\core\\interactiveshell.py\", line 3444, in run_code\n",
      "    exec(code_obj, self.user_global_ns, self.user_ns)\n",
      "  File \"C:\\Users\\zlope\\AppData\\Local\\Temp/ipykernel_4588/3990386595.py\", line 6, in <module>\n",
      "    verbose=1)\n",
      "  File \"C:\\Users\\zlope\\miniconda3\\envs\\tensorflow\\lib\\site-packages\\tensorflow_core\\python\\keras\\engine\\training.py\", line 819, in fit\n",
      "    use_multiprocessing=use_multiprocessing)\n",
      "  File \"C:\\Users\\zlope\\miniconda3\\envs\\tensorflow\\lib\\site-packages\\tensorflow_core\\python\\keras\\engine\\training_v2.py\", line 342, in fit\n",
      "    total_epochs=epochs)\n",
      "  File \"C:\\Users\\zlope\\miniconda3\\envs\\tensorflow\\lib\\site-packages\\tensorflow_core\\python\\keras\\engine\\training_v2.py\", line 128, in run_one_epoch\n",
      "    batch_outs = execution_function(iterator)\n",
      "  File \"C:\\Users\\zlope\\miniconda3\\envs\\tensorflow\\lib\\site-packages\\tensorflow_core\\python\\keras\\engine\\training_v2_utils.py\", line 98, in execution_function\n",
      "    distributed_function(input_fn))\n",
      "  File \"C:\\Users\\zlope\\miniconda3\\envs\\tensorflow\\lib\\site-packages\\tensorflow_core\\python\\eager\\def_function.py\", line 568, in __call__\n",
      "    result = self._call(*args, **kwds)\n",
      "  File \"C:\\Users\\zlope\\miniconda3\\envs\\tensorflow\\lib\\site-packages\\tensorflow_core\\python\\eager\\def_function.py\", line 632, in _call\n",
      "    return self._stateless_fn(*args, **kwds)\n",
      "  File \"C:\\Users\\zlope\\miniconda3\\envs\\tensorflow\\lib\\site-packages\\tensorflow_core\\python\\eager\\function.py\", line 2363, in __call__\n",
      "    return graph_function._filtered_call(args, kwargs)  # pylint: disable=protected-access\n",
      "  File \"C:\\Users\\zlope\\miniconda3\\envs\\tensorflow\\lib\\site-packages\\tensorflow_core\\python\\eager\\function.py\", line 1611, in _filtered_call\n",
      "    self.captured_inputs)\n",
      "  File \"C:\\Users\\zlope\\miniconda3\\envs\\tensorflow\\lib\\site-packages\\tensorflow_core\\python\\eager\\function.py\", line 1692, in _call_flat\n",
      "    ctx, args, cancellation_manager=cancellation_manager))\n",
      "  File \"C:\\Users\\zlope\\miniconda3\\envs\\tensorflow\\lib\\site-packages\\tensorflow_core\\python\\eager\\function.py\", line 545, in call\n",
      "    ctx=ctx)\n",
      "  File \"C:\\Users\\zlope\\miniconda3\\envs\\tensorflow\\lib\\site-packages\\tensorflow_core\\python\\eager\\execute.py\", line 67, in quick_execute\n",
      "    six.raise_from(core._status_to_exception(e.code, message), None)\n",
      "  File \"<string>\", line 3, in raise_from\n",
      "tensorflow.python.framework.errors_impl.InternalError: 2 root error(s) found.\n",
      "  (0) Internal:  Blas GEMM launch failed : a.shape=(512, 16), b.shape=(16, 16), m=512, n=16, k=16\n",
      "\t [[node sequential_1/dense_2/MatMul (defined at \\AppData\\Local\\Temp/ipykernel_4588/3990386595.py:6) ]]\n",
      "  (1) Internal:  Blas GEMM launch failed : a.shape=(512, 16), b.shape=(16, 16), m=512, n=16, k=16\n",
      "\t [[node sequential_1/dense_2/MatMul (defined at \\AppData\\Local\\Temp/ipykernel_4588/3990386595.py:6) ]]\n",
      "\t [[Reshape_12/_46]]\n",
      "0 successful operations.\n",
      "0 derived errors ignored. [Op:__inference_distributed_function_1967]\n",
      "\n",
      "Function call stack:\n",
      "distributed_function -> distributed_function\n",
      "\n",
      "\n",
      "During handling of the above exception, another exception occurred:\n",
      "\n",
      "Traceback (most recent call last):\n",
      "  File \"C:\\Users\\zlope\\miniconda3\\envs\\tensorflow\\lib\\site-packages\\IPython\\core\\interactiveshell.py\", line 2064, in showtraceback\n",
      "    stb = value._render_traceback_()\n",
      "AttributeError: 'InternalError' object has no attribute '_render_traceback_'\n",
      "\n",
      "During handling of the above exception, another exception occurred:\n",
      "\n",
      "Traceback (most recent call last):\n",
      "  File \"C:\\Users\\zlope\\miniconda3\\envs\\tensorflow\\lib\\site-packages\\IPython\\core\\interactiveshell.py\", line 3364, in run_ast_nodes\n",
      "    if (await self.run_code(code, result,  async_=asy)):\n",
      "  File \"C:\\Users\\zlope\\miniconda3\\envs\\tensorflow\\lib\\site-packages\\IPython\\core\\interactiveshell.py\", line 3461, in run_code\n",
      "    self.showtraceback(running_compiled_code=True)\n",
      "  File \"C:\\Users\\zlope\\miniconda3\\envs\\tensorflow\\lib\\site-packages\\IPython\\core\\interactiveshell.py\", line 2067, in showtraceback\n",
      "    value, tb, tb_offset=tb_offset)\n",
      "  File \"C:\\Users\\zlope\\miniconda3\\envs\\tensorflow\\lib\\site-packages\\IPython\\core\\ultratb.py\", line 1368, in structured_traceback\n",
      "    self, etype, value, tb, tb_offset, number_of_lines_of_context)\n",
      "  File \"C:\\Users\\zlope\\miniconda3\\envs\\tensorflow\\lib\\site-packages\\IPython\\core\\ultratb.py\", line 1268, in structured_traceback\n",
      "    self, etype, value, tb, tb_offset, number_of_lines_of_context\n",
      "  File \"C:\\Users\\zlope\\miniconda3\\envs\\tensorflow\\lib\\site-packages\\IPython\\core\\ultratb.py\", line 1125, in structured_traceback\n",
      "    tb_offset)\n",
      "  File \"C:\\Users\\zlope\\miniconda3\\envs\\tensorflow\\lib\\site-packages\\IPython\\core\\ultratb.py\", line 1082, in format_exception_as_a_whole\n",
      "    last_unique, recursion_repeat = find_recursion(orig_etype, evalue, records)\n",
      "  File \"C:\\Users\\zlope\\miniconda3\\envs\\tensorflow\\lib\\site-packages\\IPython\\core\\ultratb.py\", line 382, in find_recursion\n",
      "    return len(records), 0\n",
      "TypeError: object of type 'NoneType' has no len()\n",
      "\n",
      "During handling of the above exception, another exception occurred:\n",
      "\n",
      "Traceback (most recent call last):\n",
      "  File \"C:\\Users\\zlope\\miniconda3\\envs\\tensorflow\\lib\\site-packages\\IPython\\core\\interactiveshell.py\", line 2064, in showtraceback\n",
      "    stb = value._render_traceback_()\n",
      "AttributeError: 'TypeError' object has no attribute '_render_traceback_'\n",
      "\n",
      "During handling of the above exception, another exception occurred:\n",
      "\n",
      "Traceback (most recent call last):\n",
      "  File \"C:\\Users\\zlope\\miniconda3\\envs\\tensorflow\\lib\\site-packages\\IPython\\core\\ultratb.py\", line 1101, in get_records\n",
      "    return _fixed_getinnerframes(etb, number_of_lines_of_context, tb_offset)\n",
      "  File \"C:\\Users\\zlope\\miniconda3\\envs\\tensorflow\\lib\\site-packages\\IPython\\core\\ultratb.py\", line 248, in wrapped\n",
      "    return f(*args, **kwargs)\n",
      "  File \"C:\\Users\\zlope\\miniconda3\\envs\\tensorflow\\lib\\site-packages\\IPython\\core\\ultratb.py\", line 281, in _fixed_getinnerframes\n",
      "    records = fix_frame_records_filenames(inspect.getinnerframes(etb, context))\n",
      "  File \"C:\\Users\\zlope\\miniconda3\\envs\\tensorflow\\lib\\inspect.py\", line 1502, in getinnerframes\n",
      "    frameinfo = (tb.tb_frame,) + getframeinfo(tb, context)\n",
      "  File \"C:\\Users\\zlope\\miniconda3\\envs\\tensorflow\\lib\\inspect.py\", line 1460, in getframeinfo\n",
      "    filename = getsourcefile(frame) or getfile(frame)\n",
      "  File \"C:\\Users\\zlope\\miniconda3\\envs\\tensorflow\\lib\\inspect.py\", line 696, in getsourcefile\n",
      "    if getattr(getmodule(object, filename), '__loader__', None) is not None:\n",
      "  File \"C:\\Users\\zlope\\miniconda3\\envs\\tensorflow\\lib\\inspect.py\", line 733, in getmodule\n",
      "    if ismodule(module) and hasattr(module, '__file__'):\n",
      "  File \"C:\\Users\\zlope\\miniconda3\\envs\\tensorflow\\lib\\site-packages\\tensorflow\\__init__.py\", line 50, in __getattr__\n",
      "    module = self._load()\n",
      "  File \"C:\\Users\\zlope\\miniconda3\\envs\\tensorflow\\lib\\site-packages\\tensorflow\\__init__.py\", line 44, in _load\n",
      "    module = _importlib.import_module(self.__name__)\n",
      "  File \"C:\\Users\\zlope\\miniconda3\\envs\\tensorflow\\lib\\importlib\\__init__.py\", line 127, in import_module\n",
      "    return _bootstrap._gcd_import(name[level:], package, level)\n",
      "  File \"<frozen importlib._bootstrap>\", line 1006, in _gcd_import\n",
      "  File \"<frozen importlib._bootstrap>\", line 983, in _find_and_load\n",
      "  File \"<frozen importlib._bootstrap>\", line 965, in _find_and_load_unlocked\n",
      "ModuleNotFoundError: No module named 'tensorflow_core.estimator'\n",
      "Traceback (most recent call last):\n",
      "  File \"C:\\Users\\zlope\\miniconda3\\envs\\tensorflow\\lib\\site-packages\\IPython\\core\\interactiveshell.py\", line 3444, in run_code\n",
      "    exec(code_obj, self.user_global_ns, self.user_ns)\n",
      "  File \"C:\\Users\\zlope\\AppData\\Local\\Temp/ipykernel_4588/3990386595.py\", line 6, in <module>\n",
      "    verbose=1)\n",
      "  File \"C:\\Users\\zlope\\miniconda3\\envs\\tensorflow\\lib\\site-packages\\tensorflow_core\\python\\keras\\engine\\training.py\", line 819, in fit\n",
      "    use_multiprocessing=use_multiprocessing)\n",
      "  File \"C:\\Users\\zlope\\miniconda3\\envs\\tensorflow\\lib\\site-packages\\tensorflow_core\\python\\keras\\engine\\training_v2.py\", line 342, in fit\n",
      "    total_epochs=epochs)\n",
      "  File \"C:\\Users\\zlope\\miniconda3\\envs\\tensorflow\\lib\\site-packages\\tensorflow_core\\python\\keras\\engine\\training_v2.py\", line 128, in run_one_epoch\n",
      "    batch_outs = execution_function(iterator)\n",
      "  File \"C:\\Users\\zlope\\miniconda3\\envs\\tensorflow\\lib\\site-packages\\tensorflow_core\\python\\keras\\engine\\training_v2_utils.py\", line 98, in execution_function\n",
      "    distributed_function(input_fn))\n",
      "  File \"C:\\Users\\zlope\\miniconda3\\envs\\tensorflow\\lib\\site-packages\\tensorflow_core\\python\\eager\\def_function.py\", line 568, in __call__\n",
      "    result = self._call(*args, **kwds)\n",
      "  File \"C:\\Users\\zlope\\miniconda3\\envs\\tensorflow\\lib\\site-packages\\tensorflow_core\\python\\eager\\def_function.py\", line 632, in _call\n",
      "    return self._stateless_fn(*args, **kwds)\n",
      "  File \"C:\\Users\\zlope\\miniconda3\\envs\\tensorflow\\lib\\site-packages\\tensorflow_core\\python\\eager\\function.py\", line 2363, in __call__\n",
      "    return graph_function._filtered_call(args, kwargs)  # pylint: disable=protected-access\n",
      "  File \"C:\\Users\\zlope\\miniconda3\\envs\\tensorflow\\lib\\site-packages\\tensorflow_core\\python\\eager\\function.py\", line 1611, in _filtered_call\n",
      "    self.captured_inputs)\n",
      "  File \"C:\\Users\\zlope\\miniconda3\\envs\\tensorflow\\lib\\site-packages\\tensorflow_core\\python\\eager\\function.py\", line 1692, in _call_flat\n",
      "    ctx, args, cancellation_manager=cancellation_manager))\n",
      "  File \"C:\\Users\\zlope\\miniconda3\\envs\\tensorflow\\lib\\site-packages\\tensorflow_core\\python\\eager\\function.py\", line 545, in call\n",
      "    ctx=ctx)\n",
      "  File \"C:\\Users\\zlope\\miniconda3\\envs\\tensorflow\\lib\\site-packages\\tensorflow_core\\python\\eager\\execute.py\", line 67, in quick_execute\n",
      "    six.raise_from(core._status_to_exception(e.code, message), None)\n",
      "  File \"<string>\", line 3, in raise_from\n",
      "tensorflow.python.framework.errors_impl.InternalError: 2 root error(s) found.\n",
      "  (0) Internal:  Blas GEMM launch failed : a.shape=(512, 16), b.shape=(16, 16), m=512, n=16, k=16\n",
      "\t [[node sequential_1/dense_2/MatMul (defined at \\AppData\\Local\\Temp/ipykernel_4588/3990386595.py:6) ]]\n",
      "  (1) Internal:  Blas GEMM launch failed : a.shape=(512, 16), b.shape=(16, 16), m=512, n=16, k=16\n",
      "\t [[node sequential_1/dense_2/MatMul (defined at \\AppData\\Local\\Temp/ipykernel_4588/3990386595.py:6) ]]\n",
      "\t [[Reshape_12/_46]]\n",
      "0 successful operations.\n",
      "0 derived errors ignored. [Op:__inference_distributed_function_1967]\n",
      "\n",
      "Function call stack:\n",
      "distributed_function -> distributed_function\n",
      "\n",
      "\n",
      "During handling of the above exception, another exception occurred:\n",
      "\n",
      "Traceback (most recent call last):\n",
      "  File \"C:\\Users\\zlope\\miniconda3\\envs\\tensorflow\\lib\\site-packages\\IPython\\core\\interactiveshell.py\", line 2064, in showtraceback\n",
      "    stb = value._render_traceback_()\n",
      "AttributeError: 'InternalError' object has no attribute '_render_traceback_'\n",
      "\n",
      "During handling of the above exception, another exception occurred:\n",
      "\n",
      "Traceback (most recent call last):\n",
      "  File \"C:\\Users\\zlope\\miniconda3\\envs\\tensorflow\\lib\\site-packages\\IPython\\core\\interactiveshell.py\", line 3364, in run_ast_nodes\n",
      "    if (await self.run_code(code, result,  async_=asy)):\n",
      "  File \"C:\\Users\\zlope\\miniconda3\\envs\\tensorflow\\lib\\site-packages\\IPython\\core\\interactiveshell.py\", line 3461, in run_code\n",
      "    self.showtraceback(running_compiled_code=True)\n",
      "  File \"C:\\Users\\zlope\\miniconda3\\envs\\tensorflow\\lib\\site-packages\\IPython\\core\\interactiveshell.py\", line 2067, in showtraceback\n",
      "    value, tb, tb_offset=tb_offset)\n",
      "  File \"C:\\Users\\zlope\\miniconda3\\envs\\tensorflow\\lib\\site-packages\\IPython\\core\\ultratb.py\", line 1368, in structured_traceback\n",
      "    self, etype, value, tb, tb_offset, number_of_lines_of_context)\n",
      "  File \"C:\\Users\\zlope\\miniconda3\\envs\\tensorflow\\lib\\site-packages\\IPython\\core\\ultratb.py\", line 1268, in structured_traceback\n",
      "    self, etype, value, tb, tb_offset, number_of_lines_of_context\n",
      "  File \"C:\\Users\\zlope\\miniconda3\\envs\\tensorflow\\lib\\site-packages\\IPython\\core\\ultratb.py\", line 1125, in structured_traceback\n",
      "    tb_offset)\n",
      "  File \"C:\\Users\\zlope\\miniconda3\\envs\\tensorflow\\lib\\site-packages\\IPython\\core\\ultratb.py\", line 1082, in format_exception_as_a_whole\n",
      "    last_unique, recursion_repeat = find_recursion(orig_etype, evalue, records)\n",
      "  File \"C:\\Users\\zlope\\miniconda3\\envs\\tensorflow\\lib\\site-packages\\IPython\\core\\ultratb.py\", line 382, in find_recursion\n",
      "    return len(records), 0\n",
      "TypeError: object of type 'NoneType' has no len()\n",
      "\n",
      "During handling of the above exception, another exception occurred:\n",
      "\n",
      "Traceback (most recent call last):\n",
      "  File \"C:\\Users\\zlope\\miniconda3\\envs\\tensorflow\\lib\\site-packages\\IPython\\core\\interactiveshell.py\", line 2064, in showtraceback\n",
      "    stb = value._render_traceback_()\n",
      "AttributeError: 'TypeError' object has no attribute '_render_traceback_'\n",
      "\n",
      "During handling of the above exception, another exception occurred:\n",
      "\n",
      "Traceback (most recent call last):\n",
      "  File \"C:\\Users\\zlope\\miniconda3\\envs\\tensorflow\\lib\\site-packages\\IPython\\core\\interactiveshell.py\", line 2947, in _run_cell\n",
      "    return runner(coro)\n",
      "  File \"C:\\Users\\zlope\\miniconda3\\envs\\tensorflow\\lib\\site-packages\\IPython\\core\\async_helpers.py\", line 68, in _pseudo_sync_runner\n",
      "    coro.send(None)\n",
      "  File \"C:\\Users\\zlope\\miniconda3\\envs\\tensorflow\\lib\\site-packages\\IPython\\core\\interactiveshell.py\", line 3173, in run_cell_async\n",
      "    interactivity=interactivity, compiler=compiler, result=result)\n",
      "  File \"C:\\Users\\zlope\\miniconda3\\envs\\tensorflow\\lib\\site-packages\\IPython\\core\\interactiveshell.py\", line 3383, in run_ast_nodes\n",
      "    self.showtraceback()\n",
      "  File \"C:\\Users\\zlope\\miniconda3\\envs\\tensorflow\\lib\\site-packages\\IPython\\core\\interactiveshell.py\", line 2067, in showtraceback\n",
      "    value, tb, tb_offset=tb_offset)\n",
      "  File \"C:\\Users\\zlope\\miniconda3\\envs\\tensorflow\\lib\\site-packages\\IPython\\core\\ultratb.py\", line 1368, in structured_traceback\n",
      "    self, etype, value, tb, tb_offset, number_of_lines_of_context)\n",
      "  File \"C:\\Users\\zlope\\miniconda3\\envs\\tensorflow\\lib\\site-packages\\IPython\\core\\ultratb.py\", line 1268, in structured_traceback\n",
      "    self, etype, value, tb, tb_offset, number_of_lines_of_context\n",
      "  File \"C:\\Users\\zlope\\miniconda3\\envs\\tensorflow\\lib\\site-packages\\IPython\\core\\ultratb.py\", line 1143, in structured_traceback\n",
      "    chained_exceptions_tb_offset)\n",
      "  File \"C:\\Users\\zlope\\miniconda3\\envs\\tensorflow\\lib\\site-packages\\IPython\\core\\ultratb.py\", line 1082, in format_exception_as_a_whole\n",
      "    last_unique, recursion_repeat = find_recursion(orig_etype, evalue, records)\n",
      "  File \"C:\\Users\\zlope\\miniconda3\\envs\\tensorflow\\lib\\site-packages\\IPython\\core\\ultratb.py\", line 382, in find_recursion\n",
      "    return len(records), 0\n",
      "TypeError: object of type 'NoneType' has no len()\n",
      "\n",
      "During handling of the above exception, another exception occurred:\n",
      "\n",
      "Traceback (most recent call last):\n",
      "  File \"C:\\Users\\zlope\\miniconda3\\envs\\tensorflow\\lib\\site-packages\\IPython\\core\\interactiveshell.py\", line 2064, in showtraceback\n",
      "    stb = value._render_traceback_()\n",
      "AttributeError: 'TypeError' object has no attribute '_render_traceback_'\n",
      "\n",
      "During handling of the above exception, another exception occurred:\n",
      "\n",
      "Traceback (most recent call last):\n",
      "  File \"C:\\Users\\zlope\\miniconda3\\envs\\tensorflow\\lib\\site-packages\\IPython\\core\\ultratb.py\", line 1101, in get_records\n",
      "    return _fixed_getinnerframes(etb, number_of_lines_of_context, tb_offset)\n",
      "  File \"C:\\Users\\zlope\\miniconda3\\envs\\tensorflow\\lib\\site-packages\\IPython\\core\\ultratb.py\", line 248, in wrapped\n",
      "    return f(*args, **kwargs)\n",
      "  File \"C:\\Users\\zlope\\miniconda3\\envs\\tensorflow\\lib\\site-packages\\IPython\\core\\ultratb.py\", line 281, in _fixed_getinnerframes\n",
      "    records = fix_frame_records_filenames(inspect.getinnerframes(etb, context))\n",
      "  File \"C:\\Users\\zlope\\miniconda3\\envs\\tensorflow\\lib\\inspect.py\", line 1502, in getinnerframes\n",
      "    frameinfo = (tb.tb_frame,) + getframeinfo(tb, context)\n",
      "  File \"C:\\Users\\zlope\\miniconda3\\envs\\tensorflow\\lib\\inspect.py\", line 1460, in getframeinfo\n",
      "    filename = getsourcefile(frame) or getfile(frame)\n",
      "  File \"C:\\Users\\zlope\\miniconda3\\envs\\tensorflow\\lib\\inspect.py\", line 696, in getsourcefile\n",
      "    if getattr(getmodule(object, filename), '__loader__', None) is not None:\n",
      "  File \"C:\\Users\\zlope\\miniconda3\\envs\\tensorflow\\lib\\inspect.py\", line 733, in getmodule\n",
      "    if ismodule(module) and hasattr(module, '__file__'):\n",
      "  File \"C:\\Users\\zlope\\miniconda3\\envs\\tensorflow\\lib\\site-packages\\tensorflow\\__init__.py\", line 50, in __getattr__\n",
      "    module = self._load()\n",
      "  File \"C:\\Users\\zlope\\miniconda3\\envs\\tensorflow\\lib\\site-packages\\tensorflow\\__init__.py\", line 44, in _load\n",
      "    module = _importlib.import_module(self.__name__)\n",
      "  File \"C:\\Users\\zlope\\miniconda3\\envs\\tensorflow\\lib\\importlib\\__init__.py\", line 127, in import_module\n",
      "    return _bootstrap._gcd_import(name[level:], package, level)\n",
      "  File \"<frozen importlib._bootstrap>\", line 1006, in _gcd_import\n",
      "  File \"<frozen importlib._bootstrap>\", line 983, in _find_and_load\n",
      "  File \"<frozen importlib._bootstrap>\", line 965, in _find_and_load_unlocked\n",
      "ModuleNotFoundError: No module named 'tensorflow_core.estimator'\n"
     ]
    }
   ],
   "source": [
    "history = model.fit(partial_x_train,\n",
    "                    partial_y_train,\n",
    "                    epochs=40,\n",
    "                    batch_size=512,\n",
    "                    validation_data=(x_val, y_val),\n",
    "                    verbose=1)"
   ]
  },
  {
   "cell_type": "code",
   "execution_count": null,
   "id": "8ef0596d",
   "metadata": {},
   "outputs": [],
   "source": []
  }
 ],
 "metadata": {
  "kernelspec": {
   "display_name": "Python 3.6 (tensorflow)",
   "language": "python",
   "name": "tensorflow"
  },
  "language_info": {
   "codemirror_mode": {
    "name": "ipython",
    "version": 3
   },
   "file_extension": ".py",
   "mimetype": "text/x-python",
   "name": "python",
   "nbconvert_exporter": "python",
   "pygments_lexer": "ipython3",
   "version": "3.7.11"
  }
 },
 "nbformat": 4,
 "nbformat_minor": 5
}
